<?xml version="1.0" encoding="utf-8"?>
<!-- =================================================================================== -->
<!-- |    This document was autogenerated by xacro from xacro/robot.xacro              | -->
<!-- |    EDITING THIS FILE BY HAND IS NOT RECOMMENDED                                 | -->
<!-- =================================================================================== -->
<robot name="wr2">
  <material name="black">
    <color rgba="0.0 0.0 0.0 1.0"/>
  </material>
  <material name="blue">
    <color rgba="0.0 0.0 0.8 1.0"/>
  </material>
  <material name="green">
    <color rgba="0.0 0.8 0.0 1.0"/>
  </material>
  <material name="grey">
    <color rgba="0.2 0.2 0.2 1.0"/>
  </material>
  <material name="silver">
    <color rgba="0.913725490196 0.913725490196 0.847058823529 1.0"/>
  </material>
  <material name="orange">
    <color rgba="1.0 0.423529411765 0.0392156862745 1.0"/>
  </material>
  <material name="brown">
    <color rgba="0.870588235294 0.811764705882 0.764705882353 1.0"/>
  </material>
  <material name="red">
    <color rgba="0.8 0.0 0.0 1.0"/>
  </material>
  <material name="white">
    <color rgba="1.0 1.0 1.0 1.0"/>
  </material>
 
  <link name="base">
    <visual>
      <origin rpy="0 0 0" xyz="0 0 0"/>
      <geometry>
        <box size="0.001 0.001 0.001"/>
      </geometry>
    </visual>
  </link>
  <joint name="floating_base" type="fixed">
    <origin rpy="0 0 0" xyz="0 0 0"/>
    <parent link="base"/>
    <child link="trunk"/>
  </joint>
  <link name="trunk">
    <visual name="body_visual">
      <origin rpy="0 0 0" xyz="0 0 0"/>
      <geometry>
        <!-- <mesh filename="meshes/base_link.STL" scale="1 1 1"/> -->
        <box size="0.28 0.202 0.114"/>
      </geometry>
      <material name="silver"/>
    </visual>
    <collision name="body_collision">
      <origin rpy="0 0 0" xyz="0 0 0"/>
      <geometry>
        <!-- <mesh filename="meshes/base_link.STL" scale="1 1 1"/> -->
        <box size="0.28 0.202 0.114"/>
      </geometry>
    </collision>
    <inertial>
      <origin rpy="0 0 0" xyz="0.00067578 -0.00016652 -0.00017278"/>
      <mass value="4.9532"/>
      <inertia ixx="0.0097737" ixy="1.6081e-06" ixz="6.1042e-06" iyy="0.011213" iyz="2.3576e-05" izz="0.016784"/>
    </inertial>
  </link>
 
  <!-- <link name="base">
    <visual>
      <origin rpy="0 0 0" xyz="0 0 0"/>
      <geometry>
        <box size="0.001 0.001 0.001"/>
      </geometry>
    </visual>
    <inertial>
      <origin rpy="0 0 0" xyz="0.00067578 -0.00016652 -0.00017278"/>
      <mass value="4.9532"/>
      <inertia ixx="0.0097737" ixy="1.6081e-06" ixz="6.1042e-06" iyy="0.011213" iyz="2.3576e-05" izz="0.016784"/>
    </inertial>
  </link>
  <joint name="floating_base" type="fixed">
    <origin rpy="0 0 0" xyz="0 0 0"/>
    <parent link="base"/>
    <child link="trunk"/>
  </joint>
  <link name="trunk">
    <visual name="body_visual">
      <origin rpy="0 0 0" xyz="0 0 0"/>
      <geometry>
        <mesh filename="meshes/base_link.STL" scale="1 1 1"/>
      </geometry>
      <material name="silver"/>
      <origin rpy="0 0 0" xyz="0 0 0"/>
      <geometry>
        <box size="0.28 0.202 0.114"/>
      </geometry>
    </visual>
    <collision name="body_collision">
      <origin rpy="0 0 0" xyz="0 0 0"/>
      <geometry>
        <box size="0.28 0.202 0.114"/>
      </geometry>
    </collision>
  </link> -->
  <joint name="imu_joint" type="fixed">
    <parent link="trunk"/>
    <child link="imu_link"/>
    <origin rpy="0 0 0" xyz="0 0 0"/>
  </joint>
  <link name="imu_link">
    <inertial>
      <mass value="0.001"/>
      <origin rpy="0 0 0" xyz="0 0 0"/>
      <inertia ixx="0.0001" ixy="0" ixz="0" iyy="0.0001" iyz="0" izz="0.0001"/>
    </inertial>
    <visual>
      <origin rpy="0 0 0" xyz="0 0 0"/>
      <geometry>
        <box size="0.001 0.001 0.001"/>
      </geometry>
      <material name="red"/>
    </visual>
    <collision>
      <origin rpy="0 0 0" xyz="0 0 0"/>
      <geometry>
        <box size=".001 .001 .001"/>
      </geometry>
    </collision>
  </link>

  <joint name="FR_hip_joint" type="revolute">
    <origin rpy="0 0 0" xyz="0.1975 -0.05 0"/>
    <parent link="trunk"/>
    <child link="FR_hip"/>
    <axis xyz="1 0 0"/>
    <dynamics damping="0" friction="0"/>
    <limit effort="33.5" lower="-0.785398163397" upper="0.785398163397" velocity="21"/>
  </joint>
  <!-- <link name="FR_hip">
      <inertial>
          <mass value="0.54"/>
          <origin xyz="0.0 0.036 0."/>
          <inertia ixx="0.000381" ixy="0.000058" ixz="0.00000045" 
              iyy="0.000560" iyz="0.00000095" izz="0.000444"/>
      </inertial>
      <visual>
          <geometry>
              <mesh filename="meshes/mini_abad.obj"/>
          </geometry>
          <origin rpy="3.141592 0.0 1.5708" xyz="-0.055 0.0 0.0"/>
      </visual>
      <collision>
          <geometry>
              <mesh filename="meshes/mini_abad.obj"/>
          </geometry>
          <origin rpy="3.141592 0 1.5708" xyz="-0.055 0 0"/>
      </collision>
  </link> -->

  <!-- <link name="FR_hip">
    <visual>
      <origin rpy="1.57079632679 0 0" xyz="0 -0.045 0"/>
      <geometry>
        <cylinder length="0.04" radius="0.046"/>
      </geometry>
      <material name="silver"/>
    </visual>
    <collision>
      <origin rpy="1.57079632679 0 0" xyz="0 -0.045 0"/>
      <geometry>
        <cylinder length="0.04" radius="0.046"/>
      </geometry>
    </collision>
    <inertial>
      <origin rpy="0 0 0" xyz="-0.00541 0.00074 6e-06"/>
      <mass value="0.510299"/>
      <inertia ixx="0.00030528937" ixy="7.788013e-06" ixz="2.2016e-07" iyy="0.000590894859" iyz="1.7175e-08" izz="0.000396594572"/>
    </inertial>
  </link> -->

  <link name="FR_hip">
    <visual name="hip2_visual">
      <!-- <origin rpy="3.14159265359 0 0" xyz="0 0 0"/>
      <geometry>
        <mesh filename="meshes/hip1_Link.STL" scale="1 1 1"/>
      </geometry> -->
      <origin rpy="1.57079632679 0 0" xyz="0 -0.046 0"/>
      <geometry>
        <cylinder length="0.04" radius="0.046"/>
      </geometry>
      <material name="blue"/>
    </visual>
    <collision name="hip2_collision">
      <origin rpy="1.57079632679 0 0" xyz="0 -0.046 0"/>
      <geometry>
        <cylinder length="0.04" radius="0.046"/>
      </geometry>
    </collision>
    <inertial>
      <mass value="0.54"/>
      <origin xyz="0.0 0.036 0."/>
      <inertia ixx="0.000381" ixy="0.000058" ixz="0.00000045" 
          iyy="0.000560" iyz="0.00000095" izz="0.000444"/>
      <origin rpy="0 0 0" xyz="-0.0032616 -0.0049715 0.00038471"/>
      <mass value="0.74362"/>
      <inertia ixx="0.00045939" ixy="1.5543e-05" ixz="6.1403e-07" iyy="0.00075207" iyz="-8.2076e-07" izz="0.00049182"/>
    </inertial>
  </link>
  <joint name="FR_thigh_joint" type="revolute">
    <origin rpy="0 0 0" xyz="0 -0.0882 0"/>
    <parent link="FR_hip"/>
    <child link="FR_thigh"/>
    <axis xyz="0 -1 0"/>
    <dynamics damping="0" friction="0"/>
    <limit effort="33.5" lower="-6.28318530718" upper="6.28318530718" velocity="21"/>
  </joint>
  <link name="FR_thigh">
    <visual name="upper2_visual">
      <!-- <origin rpy="0 0 0" xyz="0 0 0"/>
      <geometry>
        <mesh filename="meshes/upper0_Link.STL" scale="1 1 1"/>
      </geometry> -->
      <origin rpy="0 1.57079632679 0" xyz="0 0 -0.1"/>
      <geometry>
        <box size="0.2 0.0245 0.034"/>
      </geometry>
      <material name="silver"/>
    </visual>
    <collision name="upper2_collision">
      <origin rpy="0 1.57079632679 0" xyz="0 0 -0.1"/>
      <geometry>
        <box size="0.2 0.0245 0.034"/>
      </geometry>
    </collision>
    <visual>
        <origin xyz="0 0 -0.2"/>
        <geometry>
            <sphere radius="0.02"/>
        </geometry>
    </visual>
    <collision>
        <origin xyz="0 0 -0.2"/>
        <geometry>
            <sphere radius="0.02"/>
        </geometry>
    </collision>
    <inertial>
      <origin rpy="0 0 0" xyz="-0.0029302 0.022321 -0.020612"/>
      <mass value="0.88958"/>
      <inertia ixx="0.0016427" ixy="-1.0138e-06" ixz="-8.5809e-05" iyy="0.0019549" iyz="-1.1651e-06" izz="0.00049228"/>
    </inertial>
  </link>
  <joint name="FR_calf_joint" type="revolute">
    <origin rpy="0 0 0" xyz="0 0 -0.2"/>
    <parent link="FR_thigh"/>
    <child link="FR_calf"/>
    <axis xyz="0 -1 0"/>
    <dynamics damping="0" friction="0"/>
    <limit effort="33.5" lower="-6.28318530718" upper="6.28318530718" velocity="21"/>
  </joint>
  <link name="FR_calf">
    <visual name="lower2_visual">
      <!-- <origin rpy="0 0 0" xyz="0 0 0"/>
      <geometry>
        <mesh filename="meshes/lower1_Link.STL" scale="1 1 1"/>
      </geometry> -->
      <origin rpy="0 1.57079632679 0" xyz="0 0 -0.1"/>
      <geometry>
        <box size="0.2 0.016 0.016"/>
      </geometry>
      <material name="blue"/>
    </visual>
    <collision name="lower2_collision">
      <origin rpy="0 1.57079632679 0" xyz="0 0 -0.1"/>
      <geometry>
        <box size="0.2 0.016 0.016"/>
      </geometry>
    </collision>
    <!-- <visual>
        <origin xyz="0 0 -0.2"/>
        <geometry>
            <sphere radius="0.02"/>
        </geometry>
    </visual>
    <collision>
        <origin xyz="0 0 -0.2"/>
        <geometry>
            <sphere radius="0.02"/>
        </geometry>
    </collision> -->
    <inertial>
      <origin rpy="0 0 0" xyz="0.0065828 -3.477e-05 -0.059038"/>
      <mass value="0.1193"/>
      <inertia ixx="0.00033774" ixy="-1.6102e-10" ixz="4.2063e-05" iyy="0.00034623" iyz="-3.8747e-09" izz="1.4561e-05"/>
    </inertial>
  </link>

  <joint name="FR_foot_fixed" type="fixed" dont_collapse="true">
    <origin rpy="0 0 0" xyz="0 0 -0.2"/>
    <parent link="FR_calf"/>
    <child link="FR_foot"/>
  </joint>
  <link name="FR_foot">
    <visual>
      <origin rpy="0 0 0" xyz="0 0 0"/>
      <geometry>
        <sphere radius="0.02"/>
      </geometry>
      <material name="white"/>
    </visual>
    <collision>
      <origin rpy="0 0 0" xyz="0 0 0"/>
      <geometry>
        <sphere radius="0.02"/>
      </geometry>
    </collision>
    <inertial>
      <mass value="0.06"/>
      <inertia ixx="9.6e-06" ixy="0.0" ixz="0.0" iyy="9.6e-06" iyz="0.0" izz="9.6e-06"/>
    </inertial>
  </link>


  <joint name="FL_hip_joint" type="revolute">
    <origin rpy="0 0 0" xyz="0.1975 0.05 0"/>
    <parent link="trunk"/>
    <child link="FL_hip"/>
    <axis xyz="1 0 0"/>
    <dynamics damping="0" friction="0"/>
    <limit effort="33.5" lower="-0.785398163397" upper="0.785398163397" velocity="21"/>
  </joint>
  <!-- <link name="FL_hip">
      <inertial>
          <mass value="0.54"/>
          <origin xyz="0.0 0.036 0."/>
          <inertia ixx="0.000381" ixy="0.000058" ixz="0.00000045" 
              iyy="0.000560" iyz="0.00000095" izz="0.000444"/>
      </inertial>
      <visual>
          <geometry>
              <mesh filename="meshes/mini_abad.obj"/>
          </geometry>
          <origin rpy="0. 0. -1.5708" xyz="-0.055 0.0 0.0"/>
      </visual>
      <collision>
          <geometry>
              <mesh filename="meshes/mini_abad.obj"/>
          </geometry>
          <origin rpy="0 0 -1.5708" xyz="-0.055 0 0"/>
      </collision>
  </link> -->
  <link name="FL_hip">
    <visual name="hip0_visual">
      <!-- <origin rpy="0 0 0" xyz="0 0 0"/>
      <geometry>
        <mesh filename="meshes/hip1_Link.STL" scale="1 1 1"/>
      </geometry> -->
      <origin rpy="1.57079632679 0 0" xyz="0 0.046 0"/>
      <geometry>
        <cylinder length="0.04" radius="0.046"/>
      </geometry>
      <material name="blue"/>
    </visual>
    <collision name="hip0_collision">
      <origin rpy="1.57079632679 0 0" xyz="0 0.046 0"/>
      <geometry>
        <cylinder length="0.04" radius="0.046"/>
      </geometry>
    </collision>
    <inertial>
      <origin rpy="0 0 0" xyz="-0.0032616 0.0049715 0.00038471"/>
      <mass value="0.74362"/>
      <inertia ixx="0.00045939" ixy="-1.5543e-05" ixz="6.1403e-07" iyy="0.00075207" iyz="8.2076e-07" izz="0.00049182"/>
    </inertial>
  </link>

  <!-- <link name="FL_hip">
    <visual>
      <origin rpy="1.57079632679 0 0" xyz="0 0.045 0"/>
      <geometry>
        <cylinder length="0.04" radius="0.046"/>
      </geometry>
      <material name="silver"/>
    </visual>
    <collision>
      <origin rpy="1.57079632679 0 0" xyz="0 0.046 0"/>
      <geometry>
        <cylinder length="0.04" radius="0.046"/>
      </geometry>
    </collision>
    <inertial>
      <origin rpy="0 0 0" xyz="-0.00541 -0.00074 6e-06"/>
      <mass value="0.510299"/>
      <inertia ixx="0.00030528937" ixy="-7.788013e-06" ixz="2.2016e-07" iyy="0.000590894859" iyz="-1.7175e-08" izz="0.000396594572"/>
    </inertial>
  </link> -->

  <joint name="FL_thigh_joint" type="revolute">
    <origin rpy="0 0 0" xyz="0 0.0882 0"/>
    <parent link="FL_hip"/>
    <child link="FL_thigh"/>
    <axis xyz="0 -1 0"/>
    <dynamics damping="0" friction="0"/>
    <limit effort="33.5" lower="-6.28318530718" upper="6.28318530718" velocity="21"/>
  </joint>
  <link name="FL_thigh">
    <visual name="upper0_visual">
      <!-- <origin rpy="0 0 0" xyz="0 0 0"/>
      <geometry>
        <mesh filename="meshes/upper1_Link.STL" scale="1 1 1"/>
      </geometry> -->
      <origin rpy="0 1.57079632679 0" xyz="0 0 -0.1"/>
      <geometry>
        <box size="0.2 0.0245 0.034"/>
      </geometry>
      <material name="silver"/>
    </visual>
    <collision name="upper0_collision">
      <origin rpy="0 1.57079632679 0" xyz="0 0 -0.1"/>
      <geometry>
        <box size="0.2 0.0245 0.034"/>
      </geometry>
    </collision>
    <visual>
        <origin xyz="0 0 -0.2"/>
        <geometry>
            <sphere radius="0.02"/>
        </geometry>
    </visual>
    <collision>
        <origin xyz="0 0 -0.2"/>
        <geometry>
            <sphere radius="0.02"/>
        </geometry>
    </collision>
    <inertial>
      <origin rpy="0 0 0" xyz="-0.0029302 -0.022321 -0.020612"/>
      <mass value="0.88958"/>
      <inertia ixx="0.0016427" ixy="1.0138e-06" ixz="-8.5809e-05" iyy="0.0019549" iyz="1.1651e-06" izz="0.00049228"/>
    </inertial>
  </link>
  <joint name="FL_calf_joint" type="revolute">
    <origin rpy="0 0 0" xyz="0 0 -0.2"/>
    <parent link="FL_thigh"/>
    <child link="FL_calf"/>
    <axis xyz="0 -1 0"/>
    <dynamics damping="0" friction="0"/>
    <limit effort="33.5" lower="-6.28318530718" upper="6.28318530718" velocity="21"/>
  </joint>
  <link name="FL_calf">
    <visual name="lower0_visual">
      <!-- <origin rpy="0 0 0" xyz="0 0 0"/>
      <geometry>
        <mesh filename="meshes/lower1_Link.STL" scale="1 1 1"/>
      </geometry> -->
      <origin rpy="0 1.57079632679 0" xyz="0 0 -0.1"/>
      <geometry>
        <box size="0.2 0.016 0.016"/>
      </geometry>
      <material name="blue"/>
    </visual>
    <collision name="lower0_collision">
      <origin rpy="0 1.57079632679 0" xyz="0 0 -0.1"/>
      <geometry>
        <box size="0.2 0.016 0.016"/>
      </geometry>
    </collision>
    <!-- <visual>
        <origin xyz="0 0 -0.2"/>
        <geometry>
            <sphere radius="0.02"/>
        </geometry>
    </visual>
    <collision>
        <origin xyz="0 0 -0.2"/>
        <geometry>
            <sphere radius="0.02"/>
        </geometry>
    </collision> -->
    <inertial>
      <origin rpy="0 0 0" xyz="0.0065828 -3.477e-05 -0.059038"/>
      <mass value="0.1193"/>
      <inertia ixx="0.00033774" ixy="-1.6102e-10" ixz="4.2063e-05" iyy="0.00034623" iyz="-3.8747e-09" izz="1.4561e-05"/>
    </inertial>
  </link>
  <joint name="FL_foot_fixed" type="fixed" dont_collapse="true">
    <origin rpy="0 0 0" xyz="0 0 -0.2"/>
    <parent link="FL_calf"/>
    <child link="FL_foot"/>
  </joint>
  <link name="FL_foot">
    <visual>
      <origin rpy="0 0 0" xyz="0 0 0"/>
      <geometry>
        <sphere radius="0.02"/>
      </geometry>
      <material name="white"/>
    </visual>
    <collision>
      <origin rpy="0 0 0" xyz="0 0 0"/>
      <geometry>
        <sphere radius="0.02"/>
      </geometry>
    </collision>
    <inertial>
      <mass value="0.06"/>
      <inertia ixx="9.6e-06" ixy="0.0" ixz="0.0" iyy="9.6e-06" iyz="0.0" izz="9.6e-06"/>
    </inertial>
  </link>

  
  <joint name="RR_hip_joint" type="revolute">
    <origin rpy="0 0 0" xyz="-0.1975 -0.05 0"/>
    <parent link="trunk"/>
    <child link="RR_hip"/>
    <axis xyz="1 0 0"/>
    <dynamics damping="0.5" friction="0"/>
    <limit effort="33.5" lower="-0.785398163397" upper="0.785398163397" velocity="21"/>
    <!-- <limit effort="18" lower="-1.6" upper="1.6" velocity="40"/> -->
  </joint>
  <!-- <link name="RR_hip">
      <inertial>
          <mass value="0.54"/>
          <origin xyz="0.0 0.036 0."/>
          <inertia ixx="0.000381" ixy="0.000058" ixz="0.00000045" 
              iyy="0.000560" iyz="0.00000095" izz="0.000444"/>
      </inertial>
      <visual>
          <geometry>
              <mesh filename="meshes/mini_abad.obj"/>
          </geometry>
          <origin rpy="0.0 0.0 1.5708" xyz="0.055 0.0 0.0"/>
      </visual>
      <collision>
          <geometry>
              <mesh filename="meshes/mini_abad.obj"/>
          </geometry>
          <origin rpy="0 0 1.5708" xyz="0.055 0 0"/>
      </collision>
  </link> -->
  <link name="RR_hip">
    <visual name="hip3_visual">
      <!-- <origin rpy="3.14159265359 3.14159265359 0" xyz="0 0 0"/>
      <geometry>
        <mesh filename="meshes/hip1_Link.STL" scale="1 1 1"/>
      </geometry> -->
      <origin rpy="1.57079632679 0 0" xyz="0 -0.046 0"/>
      <geometry>
        <cylinder length="0.04" radius="0.046"/>
      </geometry>
      <material name="blue"/>
    </visual>
    <collision name="hip3_collision">
      <origin rpy="1.57079632679 0 0" xyz="0 -0.046 0"/>
      <geometry>
        <cylinder length="0.04" radius="0.046"/>
      </geometry>
    </collision>
    <inertial>
      <origin rpy="0 0 0" xyz="0.0032616 -0.0049715 0.00038471"/>
      <mass value="0.74362"/>
      <inertia ixx="0.00045939" ixy="-1.5543e-05" ixz="-6.1403e-07" iyy="0.00075207" iyz="-8.2076e-07" izz="0.00049182"/>
    </inertial>
  </link>

  <!-- <link name="RR_hip">
    <visual>
      <origin rpy="1.57079632679 0 0" xyz="0 -0.045 0"/>
      <geometry>
        <cylinder length="0.04" radius="0.046"/>
      </geometry>
      <material name="silver"/>
    </visual>
    <collision>
      <origin rpy="1.57079632679 0 0" xyz="0 -0.045 0"/>
      <geometry>
        <cylinder length="0.04" radius="0.046"/>
      </geometry>
    </collision>
    <inertial>
      <origin rpy="0 0 0" xyz="0.00541 0.00074 6e-06"/>
      <mass value="0.510299"/>
      <inertia ixx="0.00030528937" ixy="-7.788013e-06" ixz="-2.2016e-07" iyy="0.000590894859" iyz="1.7175e-08" izz="0.000396594572"/>
    </inertial>
  </link> -->

  <joint name="RR_thigh_joint" type="revolute">
    <origin rpy="0 0 0" xyz="0 -0.0882 0"/>
    <parent link="RR_hip"/>
    <child link="RR_thigh"/>
    <axis xyz="0 -1 0"/>
    <dynamics damping="0" friction="0"/>
    <limit effort="33.5" lower="-6.28318530718" upper="6.28318530718" velocity="21"/>
  </joint>
  <link name="RR_thigh">
    <visual name="upper3_visual">
      <!-- <origin rpy="0 0 0" xyz="0 0 0"/>
      <geometry>
        <mesh filename="meshes/upper0_Link.STL" scale="1 1 1"/>
      </geometry> -->
      <origin rpy="0 1.57079632679 0" xyz="0 0 -0.1"/>
      <geometry>
        <box size="0.2 0.0245 0.034"/>
      </geometry>
      <material name="silver"/>
    </visual>
    <collision name="upper3_collision">
      <origin rpy="0 1.57079632679 0" xyz="0 0 -0.1"/>
      <geometry>
        <box size="0.2 0.0245 0.034"/>
      </geometry>
    </collision>
    <visual>
        <origin xyz="0 0 -0.2"/>
        <geometry>
            <sphere radius="0.02"/>
        </geometry>
    </visual>
    <collision>
        <origin xyz="0 0 -0.2"/>
        <geometry>
            <sphere radius="0.02"/>
        </geometry>
    </collision>
    <inertial>
      <origin rpy="0 0 0" xyz="-0.0029302 0.022321 -0.020612"/>
      <mass value="0.88958"/>
      <inertia ixx="0.0016427" ixy="-1.0138e-06" ixz="-8.5809e-05" iyy="0.0019549" iyz="-1.1651e-06" izz="0.00049228"/>
    </inertial>
  </link>
  <joint name="RR_calf_joint" type="revolute">
    <origin rpy="0 0 0" xyz="0 0 -0.2"/>
    <parent link="RR_thigh"/>
    <child link="RR_calf"/>
    <axis xyz="0 -1 0"/>
    <dynamics damping="0" friction="0"/>
    <limit effort="33.5" lower="-6.28318530718" upper="6.28318530718" velocity="21"/>
  </joint>
  <link name="RR_calf">
    <visual name="lower3_visual">
      <!-- <origin rpy="0 0 0" xyz="0 0 0"/>
      <geometry>
        <mesh filename="meshes/lower1_Link.STL" scale="1 1 1"/>
      </geometry> -->
      <origin rpy="0 1.57079632679 0" xyz="0 0 -0.1"/>
      <geometry>
        <box size="0.2 0.016 0.016"/>
      </geometry>
      
      <material name="blue"/>
    </visual>
    <!-- <visual>
      <origin xyz="0 0 -0.2"/>
      <geometry>
          <sphere radius="0.02"/>
      </geometry>
    </visual> -->
    <collision name="lower3_collision">
      <origin rpy="0 1.57079632679 0" xyz="0 0 -0.1"/>
      <geometry>
        <box size="0.2 0.016 0.016"/>
      </geometry>
    </collision>
    <!-- <collision>
        <origin xyz="0 0 -0.2"/>
        <geometry>
            <sphere radius="0.02"/>
        </geometry>
    </collision> -->
    <inertial>
      <origin rpy="0 0 0" xyz="0.0065828 -3.477e-05 -0.059038"/>
      <mass value="0.1193"/>
      <inertia ixx="0.00033774" ixy="-1.6102e-10" ixz="4.2063e-05" iyy="0.00034623" iyz="-3.8747e-09" izz="1.4561e-05"/>
    </inertial>
  </link>
  <joint name="RR_foot_fixed" type="fixed" dont_collapse="true">
    <origin rpy="0 0 0" xyz="0 0 -0.2"/>
    <parent link="RR_calf"/>
    <child link="RR_foot"/>
  </joint>
  <link name="RR_foot">
    <visual>
      <origin rpy="0 0 0" xyz="0 0 0"/>
      <geometry>
        <sphere radius="0.02"/>
      </geometry>
      <material name="white"/>
    </visual>
    <collision>
      <origin rpy="0 0 0" xyz="0 0 0"/>
      <geometry>
        <sphere radius="0.02"/>
      </geometry>
    </collision>
    <inertial>
      <mass value="0.06"/>
      <inertia ixx="9.6e-06" ixy="0.0" ixz="0.0" iyy="9.6e-06" iyz="0.0" izz="9.6e-06"/>
    </inertial>
  </link>

  <joint name="RL_hip_joint" type="revolute">
    <origin rpy="0 0 0" xyz="-0.1975 0.05 0"/>
    <parent link="trunk"/>
    <child link="RL_hip"/>
    <axis xyz="1 0 0"/>
    <dynamics damping="0" friction="0"/>
    <limit effort="33.5" lower="-0.785398163397" upper="0.785398163397" velocity="21"/>
  </joint>
  <!-- <link name="RL_hip">
      <inertial>
          <mass value="0.54"/>
          <origin xyz="0.0 0.036 0."/>
          <inertia ixx="0.000381" ixy="0.000058" ixz="0.00000045" 
              iyy="0.000560" iyz="0.00000095" izz="0.000444"/>
      </inertial>
      <visual>
          <geometry>
              <mesh filename="meshes/mini_abad.obj"/>
          </geometry>
          <origin rpy="3.141592 0.0 -1.5708" xyz="0.055 0.0 0.0"/>
      </visual>
      <collision>
          <geometry>
              <mesh filename="meshes/mini_abad.obj"/>
          </geometry>
          <origin rpy="3.141592 0 -1.5708" xyz="0.055 0 0"/>
      </collision>
  </link> -->
  <link name="RL_hip">
    <visual name="hip1_visual">
      <!-- <origin rpy="0 3.14159265359 0" xyz="0 0 0"/>
      <geometry>
        <mesh filename="meshes/hip1_Link.STL" scale="1 1 1"/>
      </geometry> -->
      <origin rpy="1.57079632679 0 0" xyz="0 0.046 0"/>
      <geometry>
        <cylinder length="0.04" radius="0.046"/>
      </geometry>
      <material name="blue"/>
    </visual>
    <collision name="hip1_collision">
      <origin rpy="1.57079632679 0 0" xyz="0 0.046 0"/>
      <geometry>
        <cylinder length="0.04" radius="0.046"/>
      </geometry>
    </collision>
    <inertial>
      <origin rpy="0 0 0" xyz="0.0032616 0.0049715 0.00038471"/>
      <mass value="0.74362"/>
      <inertia ixx="0.00045939" ixy="1.5543e-05" ixz="-6.1403e-07" iyy="0.00075207" iyz="8.2076e-07" izz="0.00049182"/>
    </inertial>
  </link>

  <!-- <link name="RL_hip">
    <visual>
      <origin rpy="1.57079632679 0 0" xyz="0 0.045 0"/>
      <geometry>
        <cylinder length="0.04" radius="0.046"/>
      </geometry>
      <material name="silver"/>
    </visual>
    <collision>
      <origin rpy="1.57079632679 0 0" xyz="0 0.045 0"/>
      <geometry>
        <cylinder length="0.04" radius="0.046"/>
      </geometry>
    </collision>
    <inertial>
      <origin rpy="0 0 0" xyz="0.00541 -0.00074 6e-06"/>
      <mass value="0.510299"/>
      <inertia ixx="0.00030528937" ixy="7.788013e-06" ixz="-2.2016e-07" iyy="0.000590894859" iyz="-1.7175e-08" izz="0.000396594572"/>
    </inertial>
  </link> -->


  <joint name="RL_thigh_joint" type="revolute">
    <origin rpy="0 0 0" xyz="0 0.0882 0"/>
    <parent link="RL_hip"/>
    <child link="RL_thigh"/>
    <axis xyz="0 -1 0"/>
    <dynamics damping="0" friction="0"/>
    <limit effort="33.5" lower="-6.28318530718" upper="6.28318530718" velocity="21"/>
  </joint>
  <link name="RL_thigh">
    <visual name="upper1_visual">
      <!-- <origin rpy="0 0 0" xyz="0 0 0"/>
      <geometry>
        <mesh filename="meshes/upper1_Link.STL" scale="1 1 1"/>
      </geometry> -->
      <origin rpy="0 1.57079632679 0" xyz="0 0 -0.1"/>
      <geometry>
        <box size="0.2 0.0245 0.034"/>
      </geometry>
      <material name="silver"/>
    </visual>
    <collision name="upper1_collision">
      <origin rpy="0 1.57079632679 0" xyz="0 0 -0.1"/>
      <geometry>
        <box size="0.2 0.0245 0.034"/>
      </geometry>
    </collision>
    <visual>
        <origin xyz="0 0 -0.2"/>
        <geometry>
            <sphere radius="0.02"/>
        </geometry>
    </visual>
    <collision>
        <origin xyz="0 0 -0.2"/>
        <geometry>
            <sphere radius="0.02"/>
        </geometry>
    </collision>
    <inertial>
      <origin rpy="0 0 0" xyz="-0.0029302 -0.022321 -0.020612"/>
      <mass value="0.88958"/>
      <inertia ixx="0.0016427" ixy="1.0138e-06" ixz="-8.5809e-05" iyy="0.0019549" iyz="1.1651e-06" izz="0.00049228"/>
    </inertial>
  </link>
  <joint name="RL_calf_joint" type="revolute">
    <origin rpy="0 0 0" xyz="0 0 -0.2"/>
    <parent link="RL_thigh"/>
    <child link="RL_calf"/>
    <axis xyz="0 -1 0"/>
    <dynamics damping="0" friction="0"/>
    <limit effort="33.5" lower="-6.28318530718" upper="6.28318530718" velocity="21"/>
  </joint>
  <link name="RL_calf">
    <visual name="lower1_visual">
      <!-- <origin rpy="0 0 0" xyz="0 0 0"/>
      <geometry>
        <mesh filename="meshes/lower1_Link.STL" scale="1 1 1"/>
      </geometry> -->
      <origin rpy="0 1.57079632679 0" xyz="0 0 -0.1"/>
      <geometry>
        <box size="0.2 0.016 0.016"/>
      </geometry>
      <material name="blue"/>
    </visual>
    <!-- <visual>
        <origin xyz="0 0 -0.2"/>
        <geometry>
            <sphere radius="0.02"/>
        </geometry>
    </visual> -->
    <collision name="lower1_collision">
      <origin rpy="0 1.57079632679 0" xyz="0 0 -0.1"/>
      <geometry>
        <box size="0.2 0.016 0.016"/>
      </geometry>
    </collision>
    <!-- <collision>
        <origin xyz="0 0 -0.2"/>
        <geometry>
            <sphere radius="0.02"/>
        </geometry>
    </collision> -->
    <inertial>
      <origin rpy="0 0 0" xyz="0.0065828 -3.477e-05 -0.059038"/>
      <mass value="0.1193"/>
      <inertia ixx="0.00033774" ixy="-1.6102e-10" ixz="4.2063e-05" iyy="0.00034623" iyz="-3.8747e-09" izz="1.4561e-05"/>
    </inertial>
  </link>
  <joint name="RL_foot_fixed" type="fixed" dont_collapse="true">
    <origin rpy="0 0 0" xyz="0 0 -0.2"/>
    <parent link="RL_calf"/>
    <child link="RL_foot"/>
  </joint>
  <link name="RL_foot">
    <visual>
      <origin rpy="0 0 0" xyz="0 0 0"/>
      <geometry>
        <sphere radius="0.02"/>
      </geometry>
      <material name="white"/>
    </visual>
    <collision>
      <origin rpy="0 0 0" xyz="0 0 0"/>
      <geometry>
        <sphere radius="0.02"/>
      </geometry>
    </collision>
    <inertial>
      <mass value="0.06"/>
      <inertia ixx="9.6e-06" ixy="0.0" ixz="0.0" iyy="9.6e-06" iyz="0.0" izz="9.6e-06"/>
    </inertial>
  </link>
  
</robot>
