<?xml version="1.0" encoding="utf-8"?>
<!-- =================================================================================== -->
<!-- |    This document was autogenerated by xacro from xacro/robot.xacro              | -->
<!-- |    EDITING THIS FILE BY HAND IS NOT RECOMMENDED                                 | -->
<!-- =================================================================================== -->
<robot name="wr2">
  <material name="black">
    <color rgba="0.0 0.0 0.0 1.0"/>
  </material>
  <material name="blue">
    <color rgba="0.0 0.0 0.8 1.0"/>
  </material>
  <material name="green">
    <color rgba="0.0 0.8 0.0 1.0"/>
  </material>
  <material name="grey">
    <color rgba="0.2 0.2 0.2 1.0"/>
  </material>
  <material name="silver">
    <color rgba="0.913725490196 0.913725490196 0.847058823529 1.0"/>
  </material>
  <material name="orange">
    <color rgba="1.0 0.423529411765 0.0392156862745 1.0"/>
  </material>
  <material name="brown">
    <color rgba="0.870588235294 0.811764705882 0.764705882353 1.0"/>
  </material>
  <material name="red">
    <color rgba="0.8 0.0 0.0 1.0"/>
  </material>
  <material name="white">
    <color rgba="1.0 1.0 1.0 1.0"/>
  </material>
  <!-- ros_control plugin -->
  <gazebo>
    <plugin filename="libgazebo_ros_control.so" name="gazebo_ros_control">
      <robotNamespace>/wr2</robotNamespace>
      <robotSimType>gazebo_ros_control/DefaultRobotHWSim</robotSimType>
    </plugin>
    <plugin filename="libground_truth_estimator.so" name="ground_truth_estimator">
      <updateRateHZ>500.0</updateRateHZ>
    </plugin>
  </gazebo>
  <!-- Show the trajectory of trunk center. -->
  <!-- <gazebo>
        <plugin name="3dplot" filename="libLinkPlot3DPlugin.so">
            <frequency>10</frequency>
            <plot>
                <link>body</link>
                <pose>0 0 0 0 0 0</pose>
                <material>Gazebo/Yellow</material>
            </plot>
        </plugin>
    </gazebo> -->
  <!-- Show the trajectory of foot. You can add another trajectory about another foot. -->
  <!-- <gazebo>
        <plugin name="3dplot" filename="libLinkPlot3DPlugin.so">
            <frequency>100</frequency>
            <plot>
                <link>FL_foot</link>
                <pose>0 0 0 0 0 0</pose>
                <material>Gazebo/Green</material>
            </plot>
        </plugin>
    </gazebo> -->
  <gazebo>
    <plugin filename="libgazebo_ros_force.so" name="gazebo_ros_force">
      <bodyName>trunk</bodyName>
      <topicName>/apply_force/trunk</topicName>
    </plugin>
  </gazebo>
  <gazebo reference="imu_link">
    <gravity>true</gravity>
    <sensor name="imu_sensor" type="imu">
      <always_on>true</always_on>
      <update_rate>1000</update_rate>
      <visualize>true</visualize>
      <topic>__default_topic__</topic>
      <plugin filename="libgazebo_ros_imu_sensor.so" name="imu_plugin">
        <topicName>trunk_imu</topicName>
        <bodyName>imu_link</bodyName>
        <updateRateHZ>1000.0</updateRateHZ>
        <gaussianNoise>0.0</gaussianNoise>
        <xyzOffset>0 0 0</xyzOffset>
        <rpyOffset>0 0 0</rpyOffset>
        <frameName>imu_link</frameName>
      </plugin>
      <pose>0 0 0 0 0 0</pose>
    </sensor>
  </gazebo>
  <!-- Foot contacts. -->
  <!-- <gazebo reference="lower0">
        <sensor name="FR_foot_contact" type="contact">
        <update_rate>100</update_rate>
        <plugin name="contactPlugin" filename="libunitreeFootContactPlugin.so"/>
        <contact>
            <collision>FR_calf_fixed_joint_lump__FR_foot_collision_1</collision>
        </contact>
        </sensor>
    </gazebo>
    <gazebo reference="lower1">
        <sensor name="FL_foot_contact" type="contact">
        <update_rate>100</update_rate>
        <plugin name="contactPlugin" filename="libunitreeFootContactPlugin.so"/>
        <contact>
            <collision>FL_calf_fixed_joint_lump__FL_foot_collision_1</collision>
        </contact>
        </sensor>
    </gazebo>
    <gazebo reference="lower2">
        <sensor name="RR_foot_contact" type="contact">
        <update_rate>100</update_rate>
        <plugin name="contactPlugin" filename="libunitreeFootContactPlugin.so"/>
        <contact>
            <collision>RR_calf_fixed_joint_lump__RR_foot_collision_1</collision>
        </contact>
        </sensor>
    </gazebo>
    <gazebo reference="lower3">
        <sensor name="RL_foot_contact" type="contact">
        <update_rate>100</update_rate>
        <plugin name="contactPlugin" filename="libunitreeFootContactPlugin.so"/>
        <contact>
            <collision>RL_calf_fixed_joint_lump__RL_foot_collision_1</collision>
        </contact>
        </sensor>
    </gazebo> -->
  <gazebo reference="toe0">
    <sensor name="toe0_contact" type="contact">
      <plugin filename="libgazebo_ros_bumper.so" name="toe0_plugin">
        <alwaysOn>true</alwaysOn>
        <updateRate>500</updateRate>
        <bumperTopicName>gazebo/toe0_contact_state</bumperTopicName>
        <frameName>world</frameName>
      </plugin>
      <contact>
        <collision>toe0_collision</collision>
      </contact>
      <update_rate>500</update_rate>
    </sensor>
  </gazebo>
  <gazebo reference="toe1">
    <sensor name="toe1_contact" type="contact">
      <plugin filename="libgazebo_ros_bumper.so" name="toe1_plugin">
        <alwaysOn>true</alwaysOn>
        <updateRate>500</updateRate>
        <bumperTopicName>gazebo/toe1_contact_state</bumperTopicName>
        <frameName>world</frameName>
      </plugin>
      <contact>
        <collision>toe1_collision</collision>
      </contact>
      <update_rate>500</update_rate>
    </sensor>
  </gazebo>
  <gazebo reference="toe2">
    <sensor name="toe2_contact" type="contact">
      <plugin filename="libgazebo_ros_bumper.so" name="toe2_plugin">
        <alwaysOn>true</alwaysOn>
        <updateRate>500</updateRate>
        <bumperTopicName>gazebo/toe2_contact_state</bumperTopicName>
        <frameName>world</frameName>
      </plugin>
      <contact>
        <collision>toe2_collision</collision>
      </contact>
      <update_rate>500</update_rate>
    </sensor>
  </gazebo>
  <gazebo reference="toe3">
    <sensor name="toe3_contact" type="contact">
      <plugin filename="libgazebo_ros_bumper.so" name="toe3_plugin">
        <alwaysOn>true</alwaysOn>
        <updateRate>500</updateRate>
        <bumperTopicName>gazebo/toe3_contact_state</bumperTopicName>
        <frameName>world</frameName>
      </plugin>
      <contact>
        <collision>toe3_collision</collision>
      </contact>
      <update_rate>500</update_rate>
    </sensor>
  </gazebo>
  <!-- Visualization of Foot contacts. -->
  <!-- <gazebo reference="toe0">
        <visual>
            <plugin name="drawForcePlugin" filename="libunitreeDrawForcePlugin.so">
                <topicName>FR_foot_contact</topicName>
            </plugin>
        </visual>
    </gazebo>
    <gazebo reference="toe1">
        <visual>
            <plugin name="drawForcePlugin" filename="libunitreeDrawForcePlugin.so">
                <topicName>FL_foot_contact</topicName>
            </plugin>
        </visual>
    </gazebo>
    <gazebo reference="toe2">
        <visual>
            <plugin name="drawForcePlugin" filename="libunitreeDrawForcePlugin.so">
                <topicName>RR_foot_contact</topicName>
            </plugin>
        </visual>
    </gazebo>
    <gazebo reference="toe3">
        <visual>
            <plugin name="drawForcePlugin" filename="libunitreeDrawForcePlugin.so">
                <topicName>RL_foot_contact</topicName>
            </plugin>
        </visual>
    </gazebo> -->
  <gazebo reference="body">
    <material>Gazebo/Green</material>
    <turnGravityOff>false</turnGravityOff>
  </gazebo>
  <gazebo reference="trunk">
    <mu1>0.5</mu1>
    <mu2>0.5</mu2>
    <kp value="1000000.0"/>
    <kd value="1.0"/>
  </gazebo>
  <gazebo reference="stick_link">
    <mu1>0.5</mu1>
    <mu2>0.5</mu2>
    <material>Gazebo/White</material>
  </gazebo>
  <gazebo reference="imu_link">
    <mu1>0.5</mu1>
    <mu2>0.5</mu2>
    <material>Gazebo/Red</material>
  </gazebo>
  <!-- FL leg -->
  <gazebo reference="hip0">
    <mu1>0.5</mu1>
    <mu2>0.5</mu2>
    <material>Gazebo/DarkGrey</material>
  </gazebo>
  <gazebo reference="upper0">
    <mu1>0.5</mu1>
    <mu2>0.5</mu2>
    <self_collide>0</self_collide>
    <material>Gazebo/DarkGrey</material>
    <kp value="1000000.0"/>
    <kd value="1.0"/>
  </gazebo>
  <gazebo reference="lower0">
    <mu1>0.5</mu1>
    <mu2>0.5</mu2>
    <self_collide>0</self_collide>
  </gazebo>
  <gazebo reference="toe0">
    <mu1>0.6</mu1>
    <mu2>0.6</mu2>
    <self_collide>0</self_collide>
    <material>Gazebo/DarkGrey</material>
    <kp value="1000000.0"/>
    <kd value="1.0"/>
  </gazebo>
  <!-- RL leg -->
  <gazebo reference="hip1">
    <mu1>0.5</mu1>
    <mu2>0.5</mu2>
    <material>Gazebo/DarkGrey</material>
  </gazebo>
  <gazebo reference="upper1">
    <mu1>0.5</mu1>
    <mu2>0.5</mu2>
    <self_collide>0</self_collide>
    <material>Gazebo/DarkGrey</material>
    <kp value="1000000.0"/>
    <kd value="1.0"/>
  </gazebo>
  <gazebo reference="lower1">
    <mu1>0.5</mu1>
    <mu2>0.5</mu2>
    <self_collide>0</self_collide>
  </gazebo>
  <gazebo reference="toe1">
    <mu1>0.6</mu1>
    <mu2>0.6</mu2>
    <self_collide>0</self_collide>
    <material>Gazebo/DarkGrey</material>
    <kp value="1000000.0"/>
    <kd value="1.0"/>
  </gazebo>
  <!-- FR leg -->
  <gazebo reference="hip2">
    <mu1>0.5</mu1>
    <mu2>0.5</mu2>
    <material>Gazebo/DarkGrey</material>
  </gazebo>
  <gazebo reference="upper2">
    <mu1>0.5</mu1>
    <mu2>0.5</mu2>
    <self_collide>0</self_collide>
    <material>Gazebo/DarkGrey</material>
    <kp value="1000000.0"/>
    <kd value="1.0"/>
  </gazebo>
  <gazebo reference="lower2">
    <mu1>0.5</mu1>
    <mu2>0.5</mu2>
    <self_collide>0</self_collide>
  </gazebo>
  <gazebo reference="toe2">
    <mu1>0.6</mu1>
    <mu2>0.6</mu2>
    <self_collide>0</self_collide>
    <material>Gazebo/DarkGrey</material>
    <kp value="1000000.0"/>
    <kd value="1.0"/>
  </gazebo>
  <!-- RR leg -->
  <gazebo reference="hip3">
    <mu1>0.5</mu1>
    <mu2>0.5</mu2>
    <material>Gazebo/DarkGrey</material>
  </gazebo>
  <gazebo reference="upper3">
    <mu1>0.5</mu1>
    <mu2>0.5</mu2>
    <self_collide>0</self_collide>
    <material>Gazebo/DarkGrey</material>
    <kp value="1000000.0"/>
    <kd value="1.0"/>
  </gazebo>
  <gazebo reference="lower3">
    <mu1>0.5</mu1>
    <mu2>0.5</mu2>
    <self_collide>0</self_collide>
  </gazebo>
  <gazebo reference="toe3">
    <mu1>0.6</mu1>
    <mu2>0.6</mu2>
    <self_collide>0</self_collide>
    <material>Gazebo/DarkGrey</material>
    <kp value="1000000.0"/>
    <kd value="1.0"/>
  </gazebo>
  <link name="body">
    <visual>
      <origin rpy="0 0 0" xyz="0 0 0"/>
      <geometry>
        <box size="0.001 0.001 0.001"/>
      </geometry>
    </visual>
  </link>
  <joint name="floating_base" type="fixed">
    <origin rpy="0 0 0" xyz="0 0 0"/>
    <parent link="body"/>
    <child link="trunk"/>
  </joint>
  <link name="trunk">
    <visual name="body_visual">
      <origin rpy="0 0 0" xyz="0 0 0"/>
      <geometry>
        <mesh filename="package://wr2/meshes/base_link.STL" scale="1 1 1"/>
      </geometry>
      <material name="silver"/>
    </visual>
    <collision name="body_collision">
      <origin rpy="0 0 0" xyz="0 0 0"/>
      <geometry>
        <box size="0.28 0.202 0.114"/>
      </geometry>
    </collision>
    <inertial>
      <origin rpy="0 0 0" xyz="0.00067578 -0.00016652 -0.00017278"/>
      <mass value="4.9532"/>
      <inertia ixx="0.0097737" ixy="1.6081e-06" ixz="6.1042e-06" iyy="0.011213" iyz="2.3576e-05" izz="0.016784"/>
    </inertial>
  </link>
  <joint name="imu_joint" type="fixed">
    <parent link="trunk"/>
    <child link="imu_link"/>
    <origin rpy="0 0 0" xyz="0 0 0"/>
  </joint>
  <link name="imu_link">
    <inertial>
      <mass value="0.001"/>
      <origin rpy="0 0 0" xyz="0 0 0"/>
      <inertia ixx="0.0001" ixy="0" ixz="0" iyy="0.0001" iyz="0" izz="0.0001"/>
    </inertial>
    <visual>
      <origin rpy="0 0 0" xyz="0 0 0"/>
      <geometry>
        <box size="0.001 0.001 0.001"/>
      </geometry>
      <material name="red"/>
    </visual>
    <collision>
      <origin rpy="0 0 0" xyz="0 0 0"/>
      <geometry>
        <box size=".001 .001 .001"/>
      </geometry>
    </collision>
  </link>
  <link name="hip0">
    <visual name="hip0_visual">
      <origin rpy="0 0 0" xyz="0 0 0"/>
      <geometry>
        <mesh filename="package://wr2/meshes/hip1_Link.STL" scale="1 1 1"/>
      </geometry>
      <material name="blue"/>
    </visual>
    <collision name="hip0_collision">
      <origin rpy="1.57079632679 0 0" xyz="0 0 0"/>
      <geometry>
        <cylinder length="0.04" radius="0.046"/>
      </geometry>
    </collision>
    <inertial>
      <origin rpy="0 0 0" xyz="-0.0032616 0.0049715 0.00038471"/>
      <mass value="0.74362"/>
      <inertia ixx="0.00045939" ixy="-1.5543e-05" ixz="6.1403e-07" iyy="0.00075207" iyz="8.2076e-07" izz="0.00049182"/>
    </inertial>
  </link>
  <joint name="FL_hip_joint" type="revolute">
    <origin rpy="0 0 0" xyz="0.1975 0.05 0"/>
    <parent link="trunk"/>
    <child link="hip0"/>
    <axis xyz="1 0 0"/>
    <dynamics damping="0" friction="0"/>
    <limit effort="33.5" lower="-0.785398163397" upper="0.785398163397" velocity="21"/>
  </joint>
  <!-- this link is only for collision -->
  <link name="thigh_shoulder0">
    <collision>
      <origin rpy="1.57079632679 0 0" xyz="0 0 0"/>
      <geometry>
        <cylinder length="0.032" radius="0.041"/>
      </geometry>
    </collision>
  </link>
  <joint name="hip0_fixed" type="fixed">
    <origin rpy="0 0 0" xyz="0 0.081 0"/>
    <parent link="hip0"/>
    <child link="thigh_shoulder0"/>
  </joint>
  <link name="upper0">
    <visual name="upper0_visual">
      <origin rpy="0 0 0" xyz="0 0 0"/>
      <geometry>
        <mesh filename="package://wr2/meshes/upper1_Link.STL" scale="1 1 1"/>
      </geometry>
      <material name="silver"/>
    </visual>
    <collision name="upper0_collision">
      <origin rpy="0 1.57079632679 0" xyz="0 0 -0.1"/>
      <geometry>
        <box size="0.2 0.0245 0.034"/>
      </geometry>
    </collision>
    <inertial>
      <origin rpy="0 0 0" xyz="-0.0029302 -0.022321 -0.020612"/>
      <mass value="0.88958"/>
      <inertia ixx="0.0016427" ixy="1.0138e-06" ixz="-8.5809e-05" iyy="0.0019549" iyz="1.1651e-06" izz="0.00049228"/>
    </inertial>
  </link>
  <joint name="FL_thigh_joint" type="revolute">
    <origin rpy="0 1.57079632679 0" xyz="0 0.0882 0"/>
    <parent link="hip0"/>
    <child link="upper0"/>
    <axis xyz="0 -1 0"/>
    <dynamics damping="0" friction="0"/>
    <limit effort="33.5" lower="-6.28318530718" upper="6.28318530718" velocity="21"/>
  </joint>
  <link name="lower0">
    <visual name="lower0_visual">
      <origin rpy="0 0 0" xyz="0 0 0"/>
      <geometry>
        <mesh filename="package://wr2/meshes/lower1_Link.STL" scale="1 1 1"/>
      </geometry>
      <material name="blue"/>
    </visual>
    <collision name="lower0_collision">
      <origin rpy="0 1.57079632679 0" xyz="0 0 -0.1"/>
      <geometry>
        <box size="0.2 0.016 0.016"/>
      </geometry>
    </collision>
    <inertial>
      <origin rpy="0 0 0" xyz="0.0065828 -3.477e-05 -0.059038"/>
      <mass value="0.1193"/>
      <inertia ixx="0.00033774" ixy="-1.6102e-10" ixz="4.2063e-05" iyy="0.00034623" iyz="-3.8747e-09" izz="1.4561e-05"/>
    </inertial>
  </link>
  <joint name="FL_calf_joint" type="revolute">
    <origin rpy="0 -3.14159265359 0" xyz="0 0 -0.2"/>
    <parent link="upper0"/>
    <child link="lower0"/>
    <axis xyz="0 1 0"/>
    <dynamics damping="0" friction="0"/>
    <limit effort="33.5" lower="-6.28318530718" upper="6.28318530718" velocity="21"/>
  </joint>
  <link name="toe0">
    <visual name="toe0_visual">
      <origin rpy="0 0 0" xyz="0 0 0"/>
      <geometry>
        <sphere radius="0.02"/>
      </geometry>
      <material name="black"/>
    </visual>
    <collision name="toe0_collision">
      <origin rpy="0 0 0" xyz="0 0 0"/>
      <geometry>
        <sphere radius="0.03"/>
      </geometry>
      <surface>
        <bounce>
          <restitution_coefficient>0</restitution_coefficient>
          <threshold>1e+06</threshold>
        </bounce>
        <friction>
          <ode>
            <mu>0.2</mu>
            <mu2>0.5</mu2>
          </ode>
          <bullet>
            <rolling_friction>0.3</rolling_friction>
            <friction2>50</friction2>
          </bullet>
        </friction>
        <contact>
          <ode>
            <kp>30000.0</kp>
            <kd>1000.0</kd>
          </ode>
          <bullet>
            <kp>30000.0</kp>
            <kd>1000.0</kd>
            <split_impulse>1</split_impulse>
            <split_impulse_penetration_threshold>-0.01</split_impulse_penetration_threshold>
          </bullet>
        </contact>
      </surface>
    </collision>
    <inertial>
      <mass value="0.013559"/>
      <inertia ixx="4.88124e-06" ixy="0.0" ixz="0.0" iyy="4.88124e-06" iyz="0.0" izz="4.88124e-06"/>
    </inertial>
  </link>
  <joint name="jtoe0" type="fixed">
    <origin rpy="0 0 0" xyz="0 0 -0.2"/>
    <parent link="lower0"/>
    <child link="toe0"/>
  </joint>
  <transmission name="transmission_8">
    <type>transmission_interface/SimpleTransmission</type>
    <joint name="8">
      <hardwareInterface>hardware_interface/EffortJointInterface</hardwareInterface>
    </joint>
    <actuator name="motor_8">
      <hardwareInterface>EffortJointInterface</hardwareInterface>
      <mechanicalReduction>1</mechanicalReduction>
    </actuator>
  </transmission>
  <transmission name="transmission_0">
    <type>transmission_interface/SimpleTransmission</type>
    <joint name="0">
      <hardwareInterface>hardware_interface/EffortJointInterface</hardwareInterface>
    </joint>
    <actuator name="motor_0">
      <hardwareInterface>EffortJointInterface</hardwareInterface>
      <mechanicalReduction>1</mechanicalReduction>
    </actuator>
  </transmission>
  <transmission name="transmission_1">
    <type>transmission_interface/SimpleTransmission</type>
    <joint name="1">
      <hardwareInterface>hardware_interface/EffortJointInterface</hardwareInterface>
    </joint>
    <actuator name="motor_1">
      <hardwareInterface>EffortJointInterface</hardwareInterface>
      <mechanicalReduction>1</mechanicalReduction>
    </actuator>
  </transmission>
  <link name="hip1">
    <visual name="hip1_visual">
      <origin rpy="0 3.14159265359 0" xyz="0 0 0"/>
      <geometry>
        <mesh filename="package://wr2/meshes/hip1_Link.STL" scale="1 1 1"/>
      </geometry>
      <material name="blue"/>
    </visual>
    <collision name="hip1_collision">
      <origin rpy="1.57079632679 0 0" xyz="0 0 0"/>
      <geometry>
        <cylinder length="0.04" radius="0.046"/>
      </geometry>
    </collision>
    <inertial>
      <origin rpy="0 0 0" xyz="0.0032616 0.0049715 0.00038471"/>
      <mass value="0.74362"/>
      <inertia ixx="0.00045939" ixy="1.5543e-05" ixz="-6.1403e-07" iyy="0.00075207" iyz="8.2076e-07" izz="0.00049182"/>
    </inertial>
  </link>
  <joint name="RL_hip_joint" type="revolute">
    <origin rpy="0 0 0" xyz="-0.1975 0.05 0"/>
    <parent link="trunk"/>
    <child link="hip1"/>
    <axis xyz="1 0 0"/>
    <dynamics damping="0" friction="0"/>
    <limit effort="33.5" lower="-0.785398163397" upper="0.785398163397" velocity="21"/>
  </joint>
  <!-- this link is only for collision -->
  <link name="thigh_shoulder1">
    <collision>
      <origin rpy="1.57079632679 0 0" xyz="0 0 0"/>
      <geometry>
        <cylinder length="0.032" radius="0.041"/>
      </geometry>
    </collision>
  </link>
  <joint name="hip1_fixed" type="fixed">
    <origin rpy="0 0 0" xyz="0 0.081 0"/>
    <parent link="hip1"/>
    <child link="thigh_shoulder1"/>
  </joint>
  <link name="upper1">
    <visual name="upper1_visual">
      <origin rpy="0 0 0" xyz="0 0 0"/>
      <geometry>
        <mesh filename="package://wr2/meshes/upper1_Link.STL" scale="1 1 1"/>
      </geometry>
      <material name="silver"/>
    </visual>
    <collision name="upper1_collision">
      <origin rpy="0 1.57079632679 0" xyz="0 0 -0.1"/>
      <geometry>
        <box size="0.2 0.0245 0.034"/>
      </geometry>
    </collision>
    <inertial>
      <origin rpy="0 0 0" xyz="-0.0029302 -0.022321 -0.020612"/>
      <mass value="0.88958"/>
      <inertia ixx="0.0016427" ixy="1.0138e-06" ixz="-8.5809e-05" iyy="0.0019549" iyz="1.1651e-06" izz="0.00049228"/>
    </inertial>
  </link>
  <joint name="RL_thigh_joint" type="revolute">
    <origin rpy="0 1.57079632679 0" xyz="0 0.0882 0"/>
    <parent link="hip1"/>
    <child link="upper1"/>
    <axis xyz="0 -1 0"/>
    <dynamics damping="0" friction="0"/>
    <limit effort="33.5" lower="-6.28318530718" upper="6.28318530718" velocity="21"/>
  </joint>
  <link name="lower1">
    <visual name="lower1_visual">
      <origin rpy="0 0 0" xyz="0 0 0"/>
      <geometry>
        <mesh filename="package://wr2/meshes/lower1_Link.STL" scale="1 1 1"/>
      </geometry>
      <material name="blue"/>
    </visual>
    <collision name="lower1_collision">
      <origin rpy="0 1.57079632679 0" xyz="0 0 -0.1"/>
      <geometry>
        <box size="0.2 0.016 0.016"/>
      </geometry>
    </collision>
    <inertial>
      <origin rpy="0 0 0" xyz="0.0065828 -3.477e-05 -0.059038"/>
      <mass value="0.1193"/>
      <inertia ixx="0.00033774" ixy="-1.6102e-10" ixz="4.2063e-05" iyy="0.00034623" iyz="-3.8747e-09" izz="1.4561e-05"/>
    </inertial>
  </link>
  <joint name="RL_calf_joint" type="revolute">
    <origin rpy="0 -3.14159265359 0" xyz="0 0 -0.2"/>
    <parent link="upper1"/>
    <child link="lower1"/>
    <axis xyz="0 1 0"/>
    <dynamics damping="0" friction="0"/>
    <limit effort="33.5" lower="-6.28318530718" upper="6.28318530718" velocity="21"/>
  </joint>
  <link name="toe1">
    <visual name="toe1_visual">
      <origin rpy="0 0 0" xyz="0 0 0"/>
      <geometry>
        <sphere radius="0.02"/>
      </geometry>
      <material name="black"/>
    </visual>
    <collision name="toe1_collision">
      <origin rpy="0 0 0" xyz="0 0 0"/>
      <geometry>
        <sphere radius="0.03"/>
      </geometry>
      <surface>
        <bounce>
          <restitution_coefficient>0</restitution_coefficient>
          <threshold>1e+06</threshold>
        </bounce>
        <friction>
          <ode>
            <mu>0.2</mu>
            <mu2>0.5</mu2>
          </ode>
          <bullet>
            <rolling_friction>0.3</rolling_friction>
            <friction2>50</friction2>
          </bullet>
        </friction>
        <contact>
          <ode>
            <kp>30000.0</kp>
            <kd>1000.0</kd>
          </ode>
          <bullet>
            <kp>30000.0</kp>
            <kd>1000.0</kd>
            <split_impulse>1</split_impulse>
            <split_impulse_penetration_threshold>-0.01</split_impulse_penetration_threshold>
          </bullet>
        </contact>
      </surface>
    </collision>
    <inertial>
      <mass value="0.013559"/>
      <inertia ixx="4.88124e-06" ixy="0.0" ixz="0.0" iyy="4.88124e-06" iyz="0.0" izz="4.88124e-06"/>
    </inertial>
  </link>
  <joint name="jtoe1" type="fixed">
    <origin rpy="0 0 0" xyz="0 0 -0.2"/>
    <parent link="lower1"/>
    <child link="toe1"/>
  </joint>
  <transmission name="transmission_9">
    <type>transmission_interface/SimpleTransmission</type>
    <joint name="9">
      <hardwareInterface>hardware_interface/EffortJointInterface</hardwareInterface>
    </joint>
    <actuator name="motor_9">
      <hardwareInterface>EffortJointInterface</hardwareInterface>
      <mechanicalReduction>1</mechanicalReduction>
    </actuator>
  </transmission>
  <transmission name="transmission_2">
    <type>transmission_interface/SimpleTransmission</type>
    <joint name="2">
      <hardwareInterface>hardware_interface/EffortJointInterface</hardwareInterface>
    </joint>
    <actuator name="motor_2">
      <hardwareInterface>EffortJointInterface</hardwareInterface>
      <mechanicalReduction>1</mechanicalReduction>
    </actuator>
  </transmission>
  <transmission name="transmission_3">
    <type>transmission_interface/SimpleTransmission</type>
    <joint name="3">
      <hardwareInterface>hardware_interface/EffortJointInterface</hardwareInterface>
    </joint>
    <actuator name="motor_3">
      <hardwareInterface>EffortJointInterface</hardwareInterface>
      <mechanicalReduction>1</mechanicalReduction>
    </actuator>
  </transmission>
  <link name="hip2">
    <visual name="hip2_visual">
      <origin rpy="3.14159265359 0 0" xyz="0 0 0"/>
      <geometry>
        <mesh filename="package://wr2/meshes/hip1_Link.STL" scale="1 1 1"/>
      </geometry>
      <material name="blue"/>
    </visual>
    <collision name="hip2_collision">
      <origin rpy="1.57079632679 0 0" xyz="0 0 0"/>
      <geometry>
        <cylinder length="0.04" radius="0.046"/>
      </geometry>
    </collision>
    <inertial>
      <origin rpy="0 0 0" xyz="-0.0032616 -0.0049715 0.00038471"/>
      <mass value="0.74362"/>
      <inertia ixx="0.00045939" ixy="1.5543e-05" ixz="6.1403e-07" iyy="0.00075207" iyz="-8.2076e-07" izz="0.00049182"/>
    </inertial>
  </link>
  <joint name="FR_hip_joint" type="revolute">
    <origin rpy="0 0 0" xyz="0.1975 -0.05 0"/>
    <parent link="trunk"/>
    <child link="hip2"/>
    <axis xyz="1 0 0"/>
    <dynamics damping="0" friction="0"/>
    <limit effort="33.5" lower="-0.785398163397" upper="0.785398163397" velocity="21"/>
  </joint>
  <!-- this link is only for collision -->
  <link name="thigh_shoulder2">
    <collision>
      <origin rpy="1.57079632679 0 0" xyz="0 0 0"/>
      <geometry>
        <cylinder length="0.032" radius="0.041"/>
      </geometry>
    </collision>
  </link>
  <joint name="hip2_fixed" type="fixed">
    <origin rpy="0 0 0" xyz="0 -0.081 0"/>
    <parent link="hip2"/>
    <child link="thigh_shoulder2"/>
  </joint>
  <link name="upper2">
    <visual name="upper2_visual">
      <origin rpy="0 0 0" xyz="0 0 0"/>
      <geometry>
        <mesh filename="package://wr2/meshes/upper0_Link.STL" scale="1 1 1"/>
      </geometry>
      <material name="silver"/>
    </visual>
    <collision name="upper2_collision">
      <origin rpy="0 1.57079632679 0" xyz="0 0 -0.1"/>
      <geometry>
        <box size="0.2 0.0245 0.034"/>
      </geometry>
    </collision>
    <inertial>
      <origin rpy="0 0 0" xyz="-0.0029302 0.022321 -0.020612"/>
      <mass value="0.88958"/>
      <inertia ixx="0.0016427" ixy="-1.0138e-06" ixz="-8.5809e-05" iyy="0.0019549" iyz="-1.1651e-06" izz="0.00049228"/>
    </inertial>
  </link>
  <joint name="FR_thigh_joint" type="revolute">
    <origin rpy="0 1.57079632679 0" xyz="0 -0.0882 0"/>
    <parent link="hip2"/>
    <child link="upper2"/>
    <axis xyz="0 -1 0"/>
    <dynamics damping="0" friction="0"/>
    <limit effort="33.5" lower="-6.28318530718" upper="6.28318530718" velocity="21"/>
  </joint>
  <link name="lower2">
    <visual name="lower2_visual">
      <origin rpy="0 0 0" xyz="0 0 0"/>
      <geometry>
        <mesh filename="package://wr2/meshes/lower1_Link.STL" scale="1 1 1"/>
      </geometry>
      <material name="blue"/>
    </visual>
    <collision name="lower2_collision">
      <origin rpy="0 1.57079632679 0" xyz="0 0 -0.1"/>
      <geometry>
        <box size="0.2 0.016 0.016"/>
      </geometry>
    </collision>
    <inertial>
      <origin rpy="0 0 0" xyz="0.0065828 -3.477e-05 -0.059038"/>
      <mass value="0.1193"/>
      <inertia ixx="0.00033774" ixy="-1.6102e-10" ixz="4.2063e-05" iyy="0.00034623" iyz="-3.8747e-09" izz="1.4561e-05"/>
    </inertial>
  </link>
  <joint name="FR_calf_joint" type="revolute">
    <origin rpy="0 -3.14159265359 0" xyz="0 0 -0.2"/>
    <parent link="upper2"/>
    <child link="lower2"/>
    <axis xyz="0 1 0"/>
    <dynamics damping="0" friction="0"/>
    <limit effort="33.5" lower="-6.28318530718" upper="6.28318530718" velocity="21"/>
  </joint>
  <link name="toe2">
    <visual name="toe2_visual">
      <origin rpy="0 0 0" xyz="0 0 0"/>
      <geometry>
        <sphere radius="0.02"/>
      </geometry>
      <material name="black"/>
    </visual>
    <collision name="toe2_collision">
      <origin rpy="0 0 0" xyz="0 0 0"/>
      <geometry>
        <sphere radius="0.03"/>
      </geometry>
      <surface>
        <bounce>
          <restitution_coefficient>0</restitution_coefficient>
          <threshold>1e+06</threshold>
        </bounce>
        <friction>
          <ode>
            <mu>0.2</mu>
            <mu2>0.5</mu2>
          </ode>
          <bullet>
            <rolling_friction>0.3</rolling_friction>
            <friction2>50</friction2>
          </bullet>
        </friction>
        <contact>
          <ode>
            <kp>30000.0</kp>
            <kd>1000.0</kd>
          </ode>
          <bullet>
            <kp>30000.0</kp>
            <kd>1000.0</kd>
            <split_impulse>1</split_impulse>
            <split_impulse_penetration_threshold>-0.01</split_impulse_penetration_threshold>
          </bullet>
        </contact>
      </surface>
    </collision>
    <inertial>
      <mass value="0.013559"/>
      <inertia ixx="4.88124e-06" ixy="0.0" ixz="0.0" iyy="4.88124e-06" iyz="0.0" izz="4.88124e-06"/>
    </inertial>
  </link>
  <joint name="jtoe2" type="fixed">
    <origin rpy="0 0 0" xyz="0 0 -0.2"/>
    <parent link="lower2"/>
    <child link="toe2"/>
  </joint>
  <transmission name="transmission_10">
    <type>transmission_interface/SimpleTransmission</type>
    <joint name="10">
      <hardwareInterface>hardware_interface/EffortJointInterface</hardwareInterface>
    </joint>
    <actuator name="motor_10">
      <hardwareInterface>EffortJointInterface</hardwareInterface>
      <mechanicalReduction>1</mechanicalReduction>
    </actuator>
  </transmission>
  <transmission name="transmission_4">
    <type>transmission_interface/SimpleTransmission</type>
    <joint name="4">
      <hardwareInterface>hardware_interface/EffortJointInterface</hardwareInterface>
    </joint>
    <actuator name="motor_4">
      <hardwareInterface>EffortJointInterface</hardwareInterface>
      <mechanicalReduction>1</mechanicalReduction>
    </actuator>
  </transmission>
  <transmission name="transmission_5">
    <type>transmission_interface/SimpleTransmission</type>
    <joint name="5">
      <hardwareInterface>hardware_interface/EffortJointInterface</hardwareInterface>
    </joint>
    <actuator name="motor_5">
      <hardwareInterface>EffortJointInterface</hardwareInterface>
      <mechanicalReduction>1</mechanicalReduction>
    </actuator>
  </transmission>
  <link name="hip3">
    <visual name="hip3_visual">
      <origin rpy="3.14159265359 3.14159265359 0" xyz="0 0 0"/>
      <geometry>
        <mesh filename="package://wr2/meshes/hip1_Link.STL" scale="1 1 1"/>
      </geometry>
      <material name="blue"/>
    </visual>
    <collision name="hip3_collision">
      <origin rpy="1.57079632679 0 0" xyz="0 0 0"/>
      <geometry>
        <cylinder length="0.04" radius="0.046"/>
      </geometry>
    </collision>
    <inertial>
      <origin rpy="0 0 0" xyz="0.0032616 -0.0049715 0.00038471"/>
      <mass value="0.74362"/>
      <inertia ixx="0.00045939" ixy="-1.5543e-05" ixz="-6.1403e-07" iyy="0.00075207" iyz="-8.2076e-07" izz="0.00049182"/>
    </inertial>
  </link>
  <joint name="RR_hip_joint" type="revolute">
    <origin rpy="0 0 0" xyz="-0.1975 -0.05 0"/>
    <parent link="trunk"/>
    <child link="hip3"/>
    <axis xyz="1 0 0"/>
    <dynamics damping="0" friction="0"/>
    <limit effort="33.5" lower="-0.785398163397" upper="0.785398163397" velocity="21"/>
  </joint>
  <!-- this link is only for collision -->
  <link name="thigh_shoulder3">
    <collision>
      <origin rpy="1.57079632679 0 0" xyz="0 0 0"/>
      <geometry>
        <cylinder length="0.032" radius="0.041"/>
      </geometry>
    </collision>
  </link>
  <joint name="hip3_fixed" type="fixed">
    <origin rpy="0 0 0" xyz="0 -0.081 0"/>
    <parent link="hip3"/>
    <child link="thigh_shoulder3"/>
  </joint>
  <link name="upper3">
    <visual name="upper3_visual">
      <origin rpy="0 0 0" xyz="0 0 0"/>
      <geometry>
        <mesh filename="package://wr2/meshes/upper0_Link.STL" scale="1 1 1"/>
      </geometry>
      <material name="silver"/>
    </visual>
    <collision name="upper3_collision">
      <origin rpy="0 1.57079632679 0" xyz="0 0 -0.1"/>
      <geometry>
        <box size="0.2 0.0245 0.034"/>
      </geometry>
    </collision>
    <inertial>
      <origin rpy="0 0 0" xyz="-0.0029302 0.022321 -0.020612"/>
      <mass value="0.88958"/>
      <inertia ixx="0.0016427" ixy="-1.0138e-06" ixz="-8.5809e-05" iyy="0.0019549" iyz="-1.1651e-06" izz="0.00049228"/>
    </inertial>
  </link>
  <joint name="RR_thigh_joint" type="revolute">
    <origin rpy="0 1.57079632679 0" xyz="0 -0.0882 0"/>
    <parent link="hip3"/>
    <child link="upper3"/>
    <axis xyz="0 -1 0"/>
    <dynamics damping="0" friction="0"/>
    <limit effort="33.5" lower="-6.28318530718" upper="6.28318530718" velocity="21"/>
  </joint>
  <link name="lower3">
    <visual name="lower3_visual">
      <origin rpy="0 0 0" xyz="0 0 0"/>
      <geometry>
        <mesh filename="package://wr2/meshes/lower1_Link.STL" scale="1 1 1"/>
      </geometry>
      <material name="blue"/>
    </visual>
    <collision name="lower3_collision">
      <origin rpy="0 1.57079632679 0" xyz="0 0 -0.1"/>
      <geometry>
        <box size="0.2 0.016 0.016"/>
      </geometry>
    </collision>
    <inertial>
      <origin rpy="0 0 0" xyz="0.0065828 -3.477e-05 -0.059038"/>
      <mass value="0.1193"/>
      <inertia ixx="0.00033774" ixy="-1.6102e-10" ixz="4.2063e-05" iyy="0.00034623" iyz="-3.8747e-09" izz="1.4561e-05"/>
    </inertial>
  </link>
  <joint name="RR_calf_joint" type="revolute">
    <origin rpy="0 -3.14159265359 0" xyz="0 0 -0.2"/>
    <parent link="upper3"/>
    <child link="lower3"/>
    <axis xyz="0 1 0"/>
    <dynamics damping="0" friction="0"/>
    <limit effort="33.5" lower="-6.28318530718" upper="6.28318530718" velocity="21"/>
  </joint>
  <link name="toe3">
    <visual name="toe3_visual">
      <origin rpy="0 0 0" xyz="0 0 0"/>
      <geometry>
        <sphere radius="0.02"/>
      </geometry>
      <material name="black"/>
    </visual>
    <collision name="toe3_collision">
      <origin rpy="0 0 0" xyz="0 0 0"/>
      <geometry>
        <sphere radius="0.03"/>
      </geometry>
      <surface>
        <bounce>
          <restitution_coefficient>0</restitution_coefficient>
          <threshold>1e+06</threshold>
        </bounce>
        <friction>
          <ode>
            <mu>0.2</mu>
            <mu2>0.5</mu2>
          </ode>
          <bullet>
            <rolling_friction>0.3</rolling_friction>
            <friction2>50</friction2>
          </bullet>
        </friction>
        <contact>
          <ode>
            <kp>30000.0</kp>
            <kd>1000.0</kd>
          </ode>
          <bullet>
            <kp>30000.0</kp>
            <kd>1000.0</kd>
            <split_impulse>1</split_impulse>
            <split_impulse_penetration_threshold>-0.01</split_impulse_penetration_threshold>
          </bullet>
        </contact>
      </surface>
    </collision>
    <inertial>
      <mass value="0.013559"/>
      <inertia ixx="4.88124e-06" ixy="0.0" ixz="0.0" iyy="4.88124e-06" iyz="0.0" izz="4.88124e-06"/>
    </inertial>
  </link>
  <joint name="jtoe3" type="fixed">
    <origin rpy="0 0 0" xyz="0 0 -0.2"/>
    <parent link="lower3"/>
    <child link="toe3"/>
  </joint>
  <transmission name="transmission_11">
    <type>transmission_interface/SimpleTransmission</type>
    <joint name="11">
      <hardwareInterface>hardware_interface/EffortJointInterface</hardwareInterface>
    </joint>
    <actuator name="motor_11">
      <hardwareInterface>EffortJointInterface</hardwareInterface>
      <mechanicalReduction>1</mechanicalReduction>
    </actuator>
  </transmission>
  <transmission name="transmission_6">
    <type>transmission_interface/SimpleTransmission</type>
    <joint name="6">
      <hardwareInterface>hardware_interface/EffortJointInterface</hardwareInterface>
    </joint>
    <actuator name="motor_6">
      <hardwareInterface>EffortJointInterface</hardwareInterface>
      <mechanicalReduction>1</mechanicalReduction>
    </actuator>
  </transmission>
  <transmission name="transmission_7">
    <type>transmission_interface/SimpleTransmission</type>
    <joint name="7">
      <hardwareInterface>hardware_interface/EffortJointInterface</hardwareInterface>
    </joint>
    <actuator name="motor_7">
      <hardwareInterface>EffortJointInterface</hardwareInterface>
      <mechanicalReduction>1</mechanicalReduction>
    </actuator>
  </transmission>

  <gazebo reference='jtoe0'>
    <preserveFixedJoint>true</preserveFixedJoint>
  </gazebo>
  <gazebo reference='jtoe1'>
    <preserveFixedJoint>true</preserveFixedJoint>
  </gazebo>
  <gazebo reference='jtoe2'>
    <preserveFixedJoint>true</preserveFixedJoint>
  </gazebo>
  <gazebo reference='jtoe3'>
    <preserveFixedJoint>true</preserveFixedJoint>
  </gazebo>
  <!-- <gazebo reference='floating_base'>
    <preserveFixedJoint>true</preserveFixedJoint>
  </gazebo> -->
  <gazebo reference='hip0_fixed'>
    <preserveFixedJoint>true</preserveFixedJoint>
  </gazebo>
  <gazebo reference='hip1_fixed'>
    <preserveFixedJoint>true</preserveFixedJoint>
  </gazebo>
  <gazebo reference='hip2_fixed'>
    <preserveFixedJoint>true</preserveFixedJoint>
  </gazebo>
  <gazebo reference='hip3_fixed'>
    <preserveFixedJoint>true</preserveFixedJoint>
  </gazebo>
</robot>
